Workbook

Sheet Ringkasan & The Ask
B1: RINGKASAN EKSEKUTIF & THE ASK
B3: MODEL BISNIS — UNIT EKONOMI
B4: Biaya AI per pesan | C4: ='Unit Ekonomi'!$C$8 | D4: Gemini 2.5 Flash-Lite, ~Rp per pesan
B5: Blended ARPU / bln | C5: ='Unit Ekonomi'!$C$16 | D5: rata-rata pendapatan / pelanggan
B6: Blended margin kotor | C6: ='Unit Ekonomi'!$C$17 | D6: SaaS dengan struktur biaya tetap
B7: LTV / pelanggan | C7: ='Unit Ekonomi'!$C$18
B9: PERTUMBUHAN
B10: Pelanggan aktif akhir Thn 1 | C10: ='Model 36 Bulan'!$N$12
B11: Pelanggan aktif akhir Thn 2 | C11: ='Model 36 Bulan'!$Z$12
B12: Pelanggan aktif akhir Thn 3 | C12: ='Model 36 Bulan'!$AL$12
B14: PENDAPATAN
B15: Pendapatan Tahun 1 | C15: =SUM('Model 36 Bulan'!$C$19:$N$19)
B16: Pendapatan Tahun 2 | C16: =SUM('Model 36 Bulan'!$O$19:$Z$19)
B17: Pendapatan Tahun 3 | C17: =SUM('Model 36 Bulan'!$AA$19:$AL$19)
B18: ARR keluar (akhir M36) | C18: ='Model 36 Bulan'!$AL$18
B20: PROFITABILITAS
B21: EBITDA Tahun 1 | C21: =SUM('Model 36 Bulan'!$C$35:$N$35)
B22: EBITDA Tahun 2 | C22: =SUM('Model 36 Bulan'!$O$35:$Z$35)
B23: EBITDA Tahun 3 | C23: =SUM('Model 36 Bulan'!$AA$35:$AL$35)
B24: Bulan mencapai profitabilitas (EBITDA+) | C24: =IF($C$40>36,"Belum dalam 36 bln",$C$40)
B25: Estimasi pelanggan saat breakeven | C25: =IF($C$40>36,"-",INDEX('Model 36 Bulan'!$C$12:$AL$12,1,$C$40))
B27: THE ASK — PENDANAAN
B28: Puncak kebutuhan kas (max burn) | C28: =MAX(0,-MIN('Model 36 Bulan'!$C$36:$AL$36)) | D28: dasar besaran raise
B29: Buffer | C29: ='Asumsi'!$C$57
B30: TARGET RAISE (seed) | C30: =CEILING(C28*(1+C29),100000000) | D30: dibulatkan ke Rp 100 jt
B31: setara (USD) | C31: =C30/'Asumsi'!$C$5 | D31: estimasi
B32: CAC (blended) | C32: =SUM('Model 36 Bulan'!$C$32:$AL$32)/SUM('Model 36 Bulan'!$C$4:$AL$4) | D32: total marketing / total akuisisi
B33: Rasio LTV : CAC | C33: =C7/C32 | D33: >3 = sehat
B34: Payback period (bln) | C34: =C32/(C5*C6) | D34: CAC / kontribusi bulanan
B36: PENGGUNAAN DANA
B37: ~55% Tim & produk (ramp ke 8 staf, 24 bln runway)
B38: ~30% Sales & Marketing (mesin akuisisi)
B39: ~15% Infra, operasional & buffer kas
B40: (helper) bln profitabilitas | C40: =MIN('Model 36 Bulan'!$C$40:$AL$40)

Sheet Asumsi
B1: CHATLY — MODEL & ASUMSI KEUANGAN
B2: Sel KUNING = bisa diedit. Semua sheet lain otomatis mengikuti. Mata uang: IDR (Rp).
B4: 1. KURS & BIAYA AI — Gemini 2.5 Flash-Lite (terverifikasi Jun 2026)
B5: Kurs USD -> IDR | C5: 18000 | E5: Rp per 1 USD (asumsi konservatif)
B6: Harga input Gemini | C6: 0.1 | E6: USD / 1 juta token
B7: Harga output Gemini | C7: 0.4 | E7: USD / 1 juta token
B8: Harga embedding (gemini-embedding-001) | C8: 0.15 | E8: USD / 1 juta token
B9: Token input / pesan | C9: 4000 | E9: system prompt + 5 chunk RAG + 6 histori + pesan masuk
B10: Token output / pesan | C10: 350 | E10: balasan + JSON intent analytics
B11: Token embedding / pesan | C11: 50 | E11: embedding query untuk RAG retrieval
B13: 2. BIAYA VARIABEL LAIN
B14: Fee payment gateway | C14: 0.029 | E14: % dari pendapatan (Xendit / Midtrans)
B15: Infra media + email / pelanggan | C15: 1500 | E15: Rp / pelanggan / bln (Cloudinary, email)
B17: 3. VOLUME PESAN AI / PELANGGAN / BULAN
B18: Starter | C18: 1500 | E18: pesan masuk ditangani AI / bln
B19: Growth | C19: 5000
B20: Pro | C20: 20000
B22: 4. HARGA PAKET (Rp / bln) — dari aplikasi
B23: Starter | C23: 149000 | E23: harga live di aplikasi
B24: Growth | C24: 349000 | E24: paket unggulan / highlighted
B25: Pro | C25: 749000
B27: 5. AKUISISI & RETENSI
B28: Pelanggan awal (bulan 1) | C28: 10 | E28: basis dari beta / early sales (konservatif)
B29: Pelanggan baru / bln — awal (M1) | C29: 10 | E29: ramp linear (konservatif)
B30: Pelanggan baru / bln — akhir (M36) | C30: 30 | E30: ramp linear (konservatif)
B31: Churn bulanan | C31: 0.05 | E31: % pelanggan berhenti / bln (SMB SaaS, konservatif)
B32: Mix Starter | C32: 0.55
B33: Mix Growth | C33: 0.35
B34: Mix Pro | C34: 0.1
B35: Cek: total mix | C35: =C32+C33+C34 | E35: harus = 100%
B37: 6. GAJI TIM (8 ORANG) — gaji gross Rp/bln, bulan mulai kerja
B38: Peran | C38: Gaji/bln | D38: Mulai bln
B39: CEO / Co-founder | C39: 3500000 | D39: 1
B40: CTO / Co-founder | C40: 3500000 | D40: 1
B41: Backend Engineer | C41: 3500000 | D41: 1
B42: Sales / Business Dev | C42: 2500000 | D42: 1
B43: Frontend Engineer | C43: 3000000 | D43: 1
B44: Customer Success | C44: 2000000 | D44: 1
B45: AI / ML Engineer | C45: 3500000 | D45: 1
B46: Growth / Marketing | C46: 2500000 | D46: 1
...

Sheet Unit Ekonomi
B1: UNIT EKONOMI — biaya per pesan & margin per tier
B3: BIAYA PER PESAN AI (Gemini 2.5 Flash-Lite)
B4: Biaya input / pesan (USD) | C4: ='Asumsi'!$C$9*'Asumsi'!$C$6/1000000
B5: Biaya output / pesan (USD) | C5: ='Asumsi'!$C$10*'Asumsi'!$C$7/1000000
B6: Biaya embedding / pesan (USD) | C6: ='Asumsi'!$C$11*'Asumsi'!$C$8/1000000
B7: Total biaya / pesan (USD) | C7: =C4+C5+C6
B8: Total biaya / pesan (Rp) | C8: =C7*'Asumsi'!$C$5 | E8: <- biaya marginal melayani 1 pesan pelanggan
B10: EKONOMI PER PELANGGAN / BULAN, PER TIER
B11: Tier | C11: Harga/bln | D11: Pesan/bln | E11: Biaya AI | F11: Fee bayar | G11: Infra | H11: Total COGS | I11: Laba kotor | J11: Margin
B12: Starter | C12: ='Asumsi'!$C$23 | D12: ='Asumsi'!$C$18 | E12: =D12*'Unit Ekonomi'!$C$8 | F12: =C12*'Asumsi'!$C$14 | G12: ='Asumsi'!$C$15 | H12: =E12+F12+G12 | I12: =C12-H12 | J12: =I12/C12
B13: Growth | C13: ='Asumsi'!$C$24 | D13: ='Asumsi'!$C$19 | E13: =D13*'Unit Ekonomi'!$C$8 | F13: =C13*'Asumsi'!$C$14 | G13: ='Asumsi'!$C$15 | H13: =E13+F13+G13 | I13: =C13-H13 | J13: =I13/C13
B14: Pro | C14: ='Asumsi'!$C$25 | D14: ='Asumsi'!$C$20 | E14: =D14*'Unit Ekonomi'!$C$8 | F14: =C14*'Asumsi'!$C$14 | G14: ='Asumsi'!$C$15 | H14: =E14+F14+G14 | I14: =C14-H14 | J14: =I14/C14
B16: Blended ARPU (Rp/bln) | C16: ='Asumsi'!$C$32*'Asumsi'!$C$23+'Asumsi'!$C$33*'Asumsi'!$C$24+'Asumsi'!$C$34*'Asumsi'!$C$25
B17: Blended margin kotor | C17: ='Asumsi'!$C$32*J12+'Asumsi'!$C$33*J13+'Asumsi'!$C$34*J14
B18: LTV / pelanggan (Rp) | C18: =C16*C17/'Asumsi'!$C$31 | E18: ARPU x margin / churn

Sheet Model 36 Bulan
B1: MODEL OPERASIONAL 36 BULAN (semua angka = formula hidup)
B3: Bulan | C3: 1 | D3: 2 | E3: 3 | F3: 4 | G3: 5 | H3: 6 | I3: 7 | J3: 8 | K3: 9 | L3: 10 | M3: 11 | N3: 12 | O3: 13 | P3: 14 | Q3: 15 | R3: 16 | S3: 17 | T3: 18 | U3: 19 | V3: 20 | W3: 21 | X3: 22 | Y3: 23 | Z3: 24 | AA3: 25 | AB3: 26 | AC3: 27 | AD3: 28 | AE3: 29 | AF3: 30 | AG3: 31 | AH3: 32 | AI3: 33 | AJ3: 34 | AK3: 35 | AL3: 36
B4: Pelanggan baru (gross) | C4: =ROUND('Asumsi'!$C$29+('Asumsi'!$C$30-'Asumsi'!$C$29)*(C$3-1)/35,0) | D4: =ROUND('Asumsi'!$C$29+('Asumsi'!$C$30-'Asumsi'!$C$29)*(D$3-1)/35,0) | E4: =ROUND('Asumsi'!$C$29+('Asumsi'!$C$30-'Asumsi'!$C$29)*(E$3-1)/35,0) | F4: =ROUND('Asumsi'!$C$29+('Asumsi'!$C$30-'Asumsi'!$C$29)*(F$3-1)/35,0) | G4: =ROUND('Asumsi'!$C$29+('Asumsi'!$C$30-'Asumsi'!$C$29)*(G$3-1)/35,0) | H4: =ROUND('Asumsi'!$C$29+('Asumsi'!$C$30-'Asumsi'!$C$29)*(H$3-1)/35,0) | I4: =ROUND('Asumsi'!$C$29+('Asumsi'!$C$30-'Asumsi'!$C$29)*(I$3-1)/35,0) | J4: =ROUND('Asumsi'!$C$29+('Asumsi'!$C$30-'Asumsi'!$C$29)*(J$3-1)/35,0) | ... AL4: =ROUND('Asumsi'!$C$29+('Asumsi'!$C$30-'Asumsi'!$C$29)*(AL$3-1)/35,0)
B5: - Starter baru | C5: =C4*'Asumsi'!$C$32 | D5: =D4*'Asumsi'!$C$32 | E5: =E4*'Asumsi'!$C$32 | F5: =F4*'Asumsi'!$C$32 | G5: =G4*'Asumsi'!$C$32 | H5: =H4*'Asumsi'!$C$32 | I5: =I4*'Asumsi'!$C$32 | J5: =J4*'Asumsi'!$C$32 | ... AL5: =AL4*'Asumsi'!$C$32
B6: - Growth baru | C6: =C4*'Asumsi'!$C$33 | D6: =D4*'Asumsi'!$C$33 | E6: =E4*'Asumsi'!$C$33 | F6: =F4*'Asumsi'!$C$33 | G6: =G4*'Asumsi'!$C$33 | H6: =H4*'Asumsi'!$C$33 | I6: =I4*'Asumsi'!$C$33 | J6: =J4*'Asumsi'!$C$33 | ... AL6: =AL4*'Asumsi'!$C$33
B7: - Pro baru | C7: =C4*'Asumsi'!$C$34 | D7: =D4*'Asumsi'!$C$34 | E7: =E4*'Asumsi'!$C$34 | F7: =F4*'Asumsi'!$C$34 | G7: =G4*'Asumsi'!$C$34 | H7: =H4*'Asumsi'!$C$34 | I7: =I4*'Asumsi'!$C$34 | J7: =J4*'Asumsi'!$C$34 | ... AL7: =AL4*'Asumsi'!$C$34
B8: PELANGGAN AKTIF
B9: Aktif Starter | C9: ='Asumsi'!$C$28*'Asumsi'!$C$32+C5 | D9: =C9*(1-'Asumsi'!$C$31)+D5 | E9: =D9*(1-'Asumsi'!$C$31)+E5 | F9: =E9*(1-'Asumsi'!$C$31)+F5 | G9: =F9*(1-'Asumsi'!$C$31)+G5 | H9: =G9*(1-'Asumsi'!$C$31)+H5 | I9: =H9*(1-'Asumsi'!$C$31)+I5 | J9: =I9*(1-'Asumsi'!$C$31)+J5 | K9: =J9*(1-'Asumsi'!$C$31)+K5 | ... AL9: =AK9*(1-'Asumsi'!$C$31)+AL5
B10: Aktif Growth | C10: ='Asumsi'!$C$28*'Asumsi'!$C$33+C6 | D10: =C10*(1-'Asumsi'!$C$31)+D6 | E10: =D10*(1-'Asumsi'!$C$31)+E6 | F10: =E10*(1-'Asumsi'!$C$31)+F6 | G10: =F10*(1-'Asumsi'!$C$31)+G6 | H10: =G10*(1-'Asumsi'!$C$31)+H6 | I10: =H10*(1-'Asumsi'!$C$31)+I6 | J10: =I10*(1-'Asumsi'!$C$31)+J6 | K10: =J10*(1-'Asumsi'!$C$31)+K6 | ... AL10: =AK10*(1-'Asumsi'!$C$31)+AL6
B11: Aktif Pro | C11: ='Asumsi'!$C$28*'Asumsi'!$C$34+C7 | D11: =C11*(1-'Asumsi'!$C$31)+D7 | E11: =D11*(1-'Asumsi'!$C$31)+E7 | F11: =E11*(1-'Asumsi'!$C$31)+F7 | G11: =F11*(1-'Asumsi'!$C$31)+G7 | H11: =G11*(1-'Asumsi'!$C$31)+H7 | I11: =H11*(1-'Asumsi'!$C$31)+I7 | J11: =I11*(1-'Asumsi'!$C$31)+J7 | K11: =J11*(1-'Asumsi'!$C$31)+K7 | ... AL11: =AK11*(1-'Asumsi'!$C$31)+AL7
B12: Total pelanggan aktif | C12: =SUM(C9:C11) | D12: =SUM(D9:D11) | E12: =SUM(E9:E11) | F12: =SUM(F9:F11) | G12: =SUM(G9:G11) | H12: =SUM(H9:H11) | I12: =SUM(I9:I11) | J12: =SUM(J9:J11) | ... AL12: =SUM(AL9:AL11)
B14: MRR Starter | C14: =C9*'Asumsi'!$C$23 | D14: =D9*'Asumsi'!$C$23 | E14: =E9*'Asumsi'!$C$23 | F14: =F9*'Asumsi'!$C$23 | G14: =G9*'Asumsi'!$C$23 | H14: =H9*'Asumsi'!$C$23 | I14: =I9*'Asumsi'!$C$23 | J14: =J9*'Asumsi'!$C$23 | ... AL14: =AL9*'Asumsi'!$C$23
B15: MRR Growth | C15: =C10*'Asumsi'!$C$24 | D15: =D10*'Asumsi'!$C$24 | E15: =E10*'Asumsi'!$C$24 | F15: =F10*'Asumsi'!$C$24 | G15: =G10*'Asumsi'!$C$24 | H15: =H10*'Asumsi'!$C$24 | I15: =I10*'Asumsi'!$C$24 | J15: =J10*'Asumsi'!$C$24 | ... AL15: =AL10*'Asumsi'!$C$24
B16: MRR Pro | C16: =C11*'Asumsi'!$C$25 | D16: =D11*'Asumsi'!$C$25 | E16: =E11*'Asumsi'!$C$25 | F16: =F11*'Asumsi'!$C$25 | G16: =G11*'Asumsi'!$C$25 | H16: =H11*'Asumsi'!$C$25 | I16: =I11*'Asumsi'!$C$25 | J16: =J11*'Asumsi'!$C$25 | ... AL16: =AL11*'Asumsi'!$C$25
B17: Total MRR | C17: =SUM(C14:C16) | D17: =SUM(D14:D16) | E17: =SUM(E14:E16) | F17: =SUM(F14:F16) | G17: =SUM(G14:G16) | H17: =SUM(H14:H16) | I17: =SUM(I14:I16) | J17: =SUM(J14:J16) | ... AL17: =SUM(AL14:AL16)
B18: ARR (MRR x 12) | C18: =C17*12 | D18: =D17*12 | E18: =E17*12 | F18: =F17*12 | G18: =G17*12 | H18: =H17*12 | I18: =I17*12 | J18: =J17*12 | ... AL18: =AL17*12
B19: PENDAPATAN bulanan | C19: =C17 | D19: =D17 | E19: =E17 | F19: =F17 | G19: =G17 | H19: =H17 | I19: =I17 | J19: =J17 | ... AL19: =AL17
B21: COGS - Biaya AI (Gemini) | C21: =(C9*'Asumsi'!$C$18+C10*'Asumsi'!$C$19+C11*'Asumsi'!$C$20)*'Unit Ekonomi'!$C$8 | D21: =(D9*'Asumsi'!$C$18+D10*'Asumsi'!$C$19+D11*'Asumsi'!$C$20)*'Unit Ekonomi'!$C$8 | E21: =(E9*'Asumsi'!$C$18+E10*'Asumsi'!$C$19+E11*'Asumsi'!$C$20)*'Unit Ekonomi'!$C$8 | F21: =(F9*'Asumsi'!$C$18+F10*'Asumsi'!$C$19+F11*'Asumsi'!$C$20)*'Unit Ekonomi'!$C$8 | G21: =(G9*'Asumsi'!$C$18+G10*'Asumsi'!$C$19+G11*'Asumsi'!$C$20)*'Unit Ekonomi'!$C$8 | H21: =(H9*'Asumsi'!$C$18+H10*'Asumsi'!$C$19+H11*'Asumsi'!$C$20)*'Unit Ekonomi'!$C$8 | I21: =(I9*'Asumsi'!$C$18+I10*'Asumsi'!$C$19+I11*'Asumsi'!$C$20)*'Unit Ekonomi'!$C$8 | J21: =(J9*'Asumsi'!$C$18+J10*'Asumsi'!$C$19+J11*'Asumsi'!$C$20)*'Unit Ekonomi'!$C$8 | ... AL21: =(AL9*'Asumsi'!$C$18+AL10*'Asumsi'!$C$19+AL11*'Asumsi'!$C$20)*'Unit Ekonomi'!$C$8
B22: COGS - Fee pembayaran | C22: =C19*'Asumsi'!$C$14 | D22: =D19*'Asumsi'!$C$14 | E22: =E19*'Asumsi'!$C$14 | F22: =F19*'Asumsi'!$C$14 | G22: =G19*'Asumsi'!$C$14 | H22: =H19*'Asumsi'!$C$14 | I22: =I19*'Asumsi'!$C$14 | J22: =J19*'Asumsi'!$C$14 | ... AL22: =AL19*'Asumsi'!$C$14
B23: COGS - Infra / media | C23: =C12*'Asumsi'!$C$15 | D23: =D12*'Asumsi'!$C$15 | E23: =E12*'Asumsi'!$C$15 | F23: =F12*'Asumsi'!$C$15 | G23: =G12*'Asumsi'!$C$15 | H23: =H12*'Asumsi'!$C$15 | I23: =I12*'Asumsi'!$C$15 | J23: =J12*'Asumsi'!$C$15 | ... AL23: =AL12*'Asumsi'!$C$15
B24: Total COGS | C24: =SUM(C21:C23) | D24: =SUM(D21:D23) | E24: =SUM(E21:E23) | F24: =SUM(F21:F23) | G24: =SUM(G21:G23) | H24: =SUM(H21:H23) | I24: =SUM(I21:I23) | J24: =SUM(J21:J23) | ... AL24: =SUM(AL21:AL23)
B25: LABA KOTOR | C25: =C19-C24 | D25: =D19-D24 | E25: =E19-E24 | F25: =F19-F24 | G25: =G19-G24 | H25: =H19-H24 | I25: =I19-I24 | J25: =J19-J24 | ... AL25: =AL19-AL24
B26: Margin kotor | C26: =C25/C19 | D26: =D25/D19 | E26: =E25/E19 | F26: =F25/F19 | G26: =G25/G19 | H26: =H25/H19 | I26: =I25/I19 | J26: =J25/J19 | ... AL26: =AL25/AL19
B28: OPEX - Gaji tim (+BPJS/THR) | C28: =(1+'Asumsi'!$C$47)*SUMPRODUCT(('Asumsi'!$D$39:$D$46<=C$3)*'Asumsi'!$C$39:$C$46) | D28: =(1+'Asumsi'!$C$47)*SUMPRODUCT(('Asumsi'!$D$39:$D$46<=D$3)*'Asumsi'!$C$39:$C$46) | E28: =(1+'Asumsi'!$C$47)*SUMPRODUCT(('Asumsi'!$D$39:$D$46<=E$3)*'Asumsi'!$C$39:$C$46) | F28: =(1+'Asumsi'!$C$47)*SUMPRODUCT(('Asumsi'!$D$39:$D$46<=F$3)*'Asumsi'!$C$39:$C$46) | G28: =(1+'Asumsi'!$C$47)*SUMPRODUCT(('Asumsi'!$D$39:$D$46<=G$3)*'Asumsi'!$C$39:$C$46) | H28: =(1+'Asumsi'!$C$47)*SUMPRODUCT(('Asumsi'!$D$39:$D$46<=H$3)*'Asumsi'!$C$39:$C$46) | I28: =(1+'Asumsi'!$C$47)*SUMPRODUCT(('Asumsi'!$D$39:$D$46<=I$3)*'Asumsi'!$C$39:$C$46) | J28: =(1+'Asumsi'!$C$47)*SUMPRODUCT(('Asumsi'!$D$39:$D$46<=J$3)*'Asumsi'!$C$39:$C$46) | ... AL28: =(1+'Asumsi'!$C$47)*SUMPRODUCT(('Asumsi'!$D$39:$D$46<=AL$3)*'Asumsi'!$C$39:$C$46)
B29: OPEX - Hosting / VPS | C29: ='Asumsi'!$C$51+('Asumsi'!$D$51-'Asumsi'!$C$51)*(C$3-1)/35 | D29: ='Asumsi'!$C$51+('Asumsi'!$D$51-'Asumsi'!$C$51)*(D$3-1)/35 | E29: ='Asumsi'!$C$51+('Asumsi'!$D$51-'Asumsi'!$C$51)*(E$3-1)/35 | F29: ='Asumsi'!$C$51+('Asumsi'!$D$51-'Asumsi'!$C$51)*(F$3-1)/35 | G29: ='Asumsi'!$C$51+('Asumsi'!$D$51-'Asumsi'!$C$51)*(G$3-1)/35 | H29: ='Asumsi'!$C$51+('Asumsi'!$D$51-'Asumsi'!$C$51)*(H$3-1)/35 | I29: ='Asumsi'!$C$51+('Asumsi'!$D$51-'Asumsi'!$C$51)*(I$3-1)/35 | J29: ='Asumsi'!$C$51+('Asumsi'!$D$51-'Asumsi'!$C$51)*(J$3-1)/35 | ... AL29: ='Asumsi'!$C$51+('Asumsi'!$D$51-'Asumsi'!$C$51)*(AL$3-1)/35
B30: OPEX - Tools & SaaS | C30: ='Asumsi'!$C$52+('Asumsi'!$D$52-'Asumsi'!$C$52)*(C$3-1)/35 | D30: ='Asumsi'!$C$52+('Asumsi'!$D$52-'Asumsi'!$C$52)*(D$3-1)/35 | E30: ='Asumsi'!$C$52+('Asumsi'!$D$52-'Asumsi'!$C$52)*(E$3-1)/35 | F30: ='Asumsi'!$C$52+('Asumsi'!$D$52-'Asumsi'!$C$52)*(F$3-1)/35 | G30: ='Asumsi'!$C$52+('Asumsi'!$D$52-'Asumsi'!$C$52)*(G$3-1)/35 | H30: ='Asumsi'!$C$52+('Asumsi'!$D$52-'Asumsi'!$C$52)*(H$3-1)/35 | I30: ='Asumsi'!$C$52+('Asumsi'!$D$52-'Asumsi'!$C$52)*(I$3-1)/35 | J30: ='Asumsi'!$C$52+('Asumsi'!$D$52-'Asumsi'!$C$52)*(J$3-1)/35 | ... AL30: ='Asumsi'!$C$52+('Asumsi'!$D$52-'Asumsi'!$C$52)*(AL$3-1)/35
B31: OPEX - Operasional & Admin | C31: ='Asumsi'!$C$53+('Asumsi'!$D$53-'Asumsi'!$C$53)*(C$3-1)/35 | D31: ='Asumsi'!$C$53+('Asumsi'!$D$53-'Asumsi'!$C$53)*(D$3-1)/35 | E31: ='Asumsi'!$C$53+('Asumsi'!$D$53-'Asumsi'!$C$53)*(E$3-1)/35 | F31: ='Asumsi'!$C$53+('Asumsi'!$D$53-'Asumsi'!$C$53)*(F$3-1)/35 | G31: ='Asumsi'!$C$53+('Asumsi'!$D$53-'Asumsi'!$C$53)*(G$3-1)/35 | H31: ='Asumsi'!$C$53+('Asumsi'!$D$53-'Asumsi'!$C$53)*(H$3-1)/35 | I31: ='Asumsi'!$C$53+('Asumsi'!$D$53-'Asumsi'!$C$53)*(I$3-1)/35 | J31: ='Asumsi'!$C$53+('Asumsi'!$D$53-'Asumsi'!$C$53)*(J$3-1)/35 | ... AL31: ='Asumsi'!$C$53+('Asumsi'!$D$53-'Asumsi'!$C$53)*(AL$3-1)/35
B32: OPEX - Sales & Marketing | C32: ='Asumsi'!$C$54+('Asumsi'!$D$54-'Asumsi'!$C$54)*(C$3-1)/35 | D32: ='Asumsi'!$C$54+('Asumsi'!$D$54-'Asumsi'!$C$54)*(D$3-1)/35 | E32: ='Asumsi'!$C$54+('Asumsi'!$D$54-'Asumsi'!$C$54)*(E$3-1)/35 | F32: ='Asumsi'!$C$54+('Asumsi'!$D$54-'Asumsi'!$C$54)*(F$3-1)/35 | G32: ='Asumsi'!$C$54+('Asumsi'!$D$54-'Asumsi'!$C$54)*(G$3-1)/35 | H32: ='Asumsi'!$C$54+('Asumsi'!$D$54-'Asumsi'!$C$54)*(H$3-1)/35 | I32: ='Asumsi'!$C$54+('Asumsi'!$D$54-'Asumsi'!$C$54)*(I$3-1)/35 | J32: ='Asumsi'!$C$54+('Asumsi'!$D$54-'Asumsi'!$C$54)*(J$3-1)/35 | ... AL32: ='Asumsi'!$C$54+('Asumsi'!$D$54-'Asumsi'!$C$54)*(AL$3-1)/35
B33: Total OPEX | C33: =SUM(C28:C32) | D33: =SUM(D28:D32) | E33: =SUM(E28:E32) | F33: =SUM(F28:F32) | G33: =SUM(G28:G32) | H33: =SUM(H28:H32) | I33: =SUM(I28:I32) | J33: =SUM(J28:J32) | ... AL33: =SUM(AL28:AL32)
B35: EBITDA | C35: =C25-C33 | D35: =D25-D33 | E35: =E25-E33 | F35: =F25-F33 | G35: =G25-G33 | H35: =H25-H33 | I35: =I25-I33 | J35: =J25-J33 | ... AL35: =AL25-AL33
B36: Arus kas kumulatif (pra-pendanaan) | C36: =C35 | D36: =C36+D35 | E36: =D36+E35 | F36: =E36+F35 | G36: =F36+G35 | H36: =G36+H35 | I36: =H36+I35 | J36: =I36+J35 | K36: =J36+K35 | ... AL36: =AK36+AL35
B38: Jumlah staf | C38: =SUMPRODUCT(('Asumsi'!$D$39:$D$46<=C$3)*1) | D38: =SUMPRODUCT(('Asumsi'!$D$39:$D$46<=D$3)*1) | E38: =SUMPRODUCT(('Asumsi'!$D$39:$D$46<=E$3)*1) | F38: =SUMPRODUCT(('Asumsi'!$D$39:$D$46<=F$3)*1) | G38: =SUMPRODUCT(('Asumsi'!$D$39:$D$46<=G$3)*1) | H38: =SUMPRODUCT(('Asumsi'!$D$39:$D$46<=H$3)*1) | I38: =SUMPRODUCT(('Asumsi'!$D$39:$D$46<=I$3)*1) | J38: =SUMPRODUCT(('Asumsi'!$D$39:$D$46<=J$3)*1) | ... AL38: =SUMPRODUCT(('Asumsi'!$D$39:$D$46<=AL$3)*1)
B40: (helper) bln profit | C40: =IF(C35>0,C$3,9999) | D40: =IF(D35>0,D$3,9999) | E40: =IF(E35>0,E$3,9999) | F40: =IF(F35>0,F$3,9999) | G40: =IF(G35>0,G$3,9999) | H40: =IF(H35>0,H$3,9999) | I40: =IF(I35>0,I$3,9999) | J40: =IF(J35>0,J$3,9999) | ... AL40: =IF(AL35>0,AL$3,9999)
